2017-12-05 22:29:25.932036: W tensorflow/core/platform/cpu_feature_guard.cc:45] The TensorFlow library wasn't compiled to use SSE4.1 instructions, but these are available on your machine and could speed up CPU computations.
2017-12-05 22:29:25.932219: W tensorflow/core/platform/cpu_feature_guard.cc:45] The TensorFlow library wasn't compiled to use SSE4.2 instructions, but these are available on your machine and could speed up CPU computations.
2017-12-05 22:29:25.940522: W tensorflow/core/platform/cpu_feature_guard.cc:45] The TensorFlow library wasn't compiled to use AVX instructions, but these are available on your machine and could speed up CPU computations.
2017-12-05 22:29:29.330779: I tensorflow/core/common_runtime/gpu/gpu_device.cc:955] Found device 0 with properties: 
name: Tesla K20Xm
major: 3 minor: 5 memoryClockRate (GHz) 0.732
pciBusID 0000:20:00.0
Total memory: 5.57GiB
Free memory: 5.49GiB
2017-12-05 22:29:29.560362: W tensorflow/stream_executor/cuda/cuda_driver.cc:523] A non-primary context 0x556656a3c740 exists before initializing the StreamExecutor. We haven't verified StreamExecutor works with that.
2017-12-05 22:29:29.561144: I tensorflow/core/common_runtime/gpu/gpu_device.cc:955] Found device 1 with properties: 
name: Tesla K20Xm
major: 3 minor: 5 memoryClockRate (GHz) 0.732
pciBusID 0000:8b:00.0
Total memory: 5.57GiB
Free memory: 5.49GiB
2017-12-05 22:29:29.561206: I tensorflow/core/common_runtime/gpu/gpu_device.cc:847] Peer access not supported between device ordinals 0 and 1
2017-12-05 22:29:29.561243: I tensorflow/core/common_runtime/gpu/gpu_device.cc:847] Peer access not supported between device ordinals 1 and 0
2017-12-05 22:29:29.561283: I tensorflow/core/common_runtime/gpu/gpu_device.cc:976] DMA: 0 1 
2017-12-05 22:29:29.561310: I tensorflow/core/common_runtime/gpu/gpu_device.cc:986] 0:   Y N 
2017-12-05 22:29:29.561328: I tensorflow/core/common_runtime/gpu/gpu_device.cc:986] 1:   N Y 
2017-12-05 22:29:29.561354: I tensorflow/core/common_runtime/gpu/gpu_device.cc:1045] Creating TensorFlow device (/gpu:0) -> (device: 0, name: Tesla K20Xm, pci bus id: 0000:20:00.0)
2017-12-05 22:29:29.561375: I tensorflow/core/common_runtime/gpu/gpu_device.cc:1045] Creating TensorFlow device (/gpu:1) -> (device: 1, name: Tesla K20Xm, pci bus id: 0000:8b:00.0)
Using TensorFlow backend.
neuralnet.py:76: UserWarning: The semantics of the Keras 2 argument `steps_per_epoch` is not the same as the Keras 1 argument `samples_per_epoch`. `steps_per_epoch` is the number of batches to draw from the generator at each epoch. Basically steps_per_epoch = samples_per_epoch/batch_size. Similarly `nb_val_samples`->`validation_steps` and `val_samples`->`steps` arguments have changed. Update your method calls accordingly.
  verbose=2)
neuralnet.py:76: UserWarning: Update your `fit_generator` call to the Keras 2 API: `fit_generator(verbose=2, generator=<generator..., validation_data=<generator..., steps_per_epoch=10144, epochs=20, validation_steps=2536)`
  verbose=2)
2017-12-05 22:29:47.218473: I tensorflow/core/common_runtime/gpu/gpu_device.cc:1045] Creating TensorFlow device (/gpu:0) -> (device: 0, name: Tesla K20Xm, pci bus id: 0000:20:00.0)
2017-12-05 22:29:47.218540: I tensorflow/core/common_runtime/gpu/gpu_device.cc:1045] Creating TensorFlow device (/gpu:1) -> (device: 1, name: Tesla K20Xm, pci bus id: 0000:8b:00.0)
Exception in thread Thread-1:
Traceback (most recent call last):
  File "/scratch/ghunkins/anaconda2/envs/keras/lib/python2.7/threading.py", line 801, in __bootstrap_inner
    self.run()
  File "/scratch/ghunkins/anaconda2/envs/keras/lib/python2.7/threading.py", line 754, in run
    self.__target(*self.__args, **self.__kwargs)
  File "/scratch/ghunkins/anaconda2/envs/keras/lib/python2.7/site-packages/keras/utils/data_utils.py", line 568, in data_generator_task
    generator_output = next(self._generator)
  File "/gpfs/fs1/home/ghunkins/Binaural-Source-Localization-CNN/Neural_Net/v3/datagenerator.py", line 34, in generate
    X, Y = self.__data_generation(list_IDs_temp)
  File "/gpfs/fs1/home/ghunkins/Binaural-Source-Localization-CNN/Neural_Net/v3/datagenerator.py", line 51, in __data_generation
    loaded_X = [np.load(data_root + ID) for ID in list_IDs_temp]
  File "/scratch/ghunkins/anaconda2/envs/keras/lib/python2.7/site-packages/numpy/lib/npyio.py", line 429, in load
    "Failed to interpret file %s as a pickle" % repr(file))
IOError: Failed to interpret file '/scratch/ghunkins/stft_binaural_0.5s/1002_SX58_0_240_1.npy' as a pickle

Traceback (most recent call last):
  File "neuralnet.py", line 76, in <module>
    verbose=2)
  File "/scratch/ghunkins/anaconda2/envs/keras/lib/python2.7/site-packages/keras/legacy/interfaces.py", line 87, in wrapper
    return func(*args, **kwargs)
  File "/scratch/ghunkins/anaconda2/envs/keras/lib/python2.7/site-packages/keras/models.py", line 1121, in fit_generator
    initial_epoch=initial_epoch)
  File "/scratch/ghunkins/anaconda2/envs/keras/lib/python2.7/site-packages/keras/legacy/interfaces.py", line 87, in wrapper
    return func(*args, **kwargs)
  File "/scratch/ghunkins/anaconda2/envs/keras/lib/python2.7/site-packages/keras/engine/training.py", line 2011, in fit_generator
    generator_output = next(output_generator)
StopIteration
